Workbook

Sheet Explications
A1: Projects with Syrphidae in the by catch
A2: Name | B2: Sampling methode | C2: years | D2: Localisation
A3: Wild bee atlas project | B3: Pantrap, Handnetting, Vane trap | C3: 2021, 2022 | D3: South, Moselle, Minett
A4: Insect reich (OUR) | B4: Malaise, Baber trap | C4: 2021 | D4: north (nature park)
A5: Beds and breakfeast birds | B5: Malaise | C5: +/- 2020 | D5: North est?
A6: MONIPOL | B6: Pantrap | C6: ?, 2021, 2022, 2023 | D6: ?
A7: Hoverfly project | B7: Handnetting | C7: 2021, 2022 | D7: ?
A10: We will have BY CATCH from different projects
A11: With the information we find we try to have the same names as for our project without lose informations
A13: Collectors name giving the name of the project
A14: wild bee atlas | B14: =WBA
A15: beds and breakfast | B15: =BNB
A16: MONIPOL | B16: =MNP
A18: Projet: Wild bee atlas
A19: site name allows you to find the coordinates in Coordinates wild bee atlas 2020-2021
A20: cell number is to be looked up according to the map created by Julian
A21: station number will always be 1
A22: Date = when the date is <10, keep the 0 at the beggining by adding ' EX: 03-05-2021 would be '030521
A23: Date in = if passive trap, put the 1rst date (when the trap was set up) OR if active, put the only date in Date out column
A24: Date out = if passive trap, put the last date (when the trap was collected) OR if active, put the only date in this column
A25: collector will always be : WBA
A27: note : name of the sites
A28: XXX-N-XXX + passive = Pantrap
A29: XXX-R-XXX + passive = Van trap
A30: XXX-N-XXX + active = Handnetting
A31: XXX-R-XXX + active = Handnetting

Sheet Problems
A1: LBB
A2: Code | B2: Latitude | C2: Longitude | D2: Cell | E2: Station | F2: Date_in | G2: Date_out | H2: Année | I2: Collecteur | J2: Code site | K2: Nom du site | L2: Passive/active | M2: Sorter | N2: Number of specimens | O2: Notes | P2: Code ID | Q2: ID | R2: IDENTIFIER | S2: NUMBER OF SPECIMEN | T2: MALE | U2: FEMALE | V2: SEX INDETERMINATE | W2: IDENTIFICATION NOTE | X2: DATE OF IDENTIFICATION | Y2: IDENTIFICATION METHOD
B3: 49.71394906 | C3: 6.272177473 | D3: 80 | E3: 3 | G3: 030721 | H3: 2021 | I3: LBB | J3: C15_p | K3: C15 | L3: malaise trap | M3: Sam Schaack | P3: vo.zo | Q3: Volucella zonaria | R3: Sam Schaack | S3: 1 | T3: 0 | U3: 1 | V3: 0 | X3: 231023 | Y3: Morphological | Z3: MNHNL81921
B4: 49.64989784 | C4: 6.417040564 | D4: 101 | E4: 1 | G4: 300821 | H4: 2021 | I4: LBB | J4: C2A_p | K4: C2A | L4: malaise trap | M4: Sam Schaack | P4: ep.ba | Q4: Episyrphus balteatus | R4: Sam Schaack | S4: 9 | T4: 2 | U4: 7 | V4: 0 | X4: 241023 | Y4: Morphological | Z4: MNHNL81771

Sheet WBA
A1: Code | B1: Latitude | C1: Longitude | D1: Cell | E1: Station | F1: Date_in | G1: Date_out | H1: Année | I1: Collecteur | J1: Code site | K1: Nom du site | L1: Passive/active | M1: Sorter | N1: Number of specimens | O1: Notes | P1: Code ID | Q1: ID | R1: IDENTIFIER | S1: NUMBER OF SPECIMEN | T1: MALE | U1: FEMALE | V1: SEX INDETERMINATE | W1: IDENTIFICATION NOTE | X1: DATE OF IDENTIFICATION | Y1: IDENTIFICATION METHOD | Z1: QR code | AA1: Recorder? | AB1: Unique
A2: =D2&"_"&E2&"_"&G2&"_"&J2&"_"&P2 -> 117_1_260821_Hoo_p_ep.ba | B2: 49.55327 | C2: 6.146631 | D2: 117 | E2: 1 | F2: 190821 | G2: 260821 | H2: 2021 | I2: Danielle Dolisy, Imen Kharrat | J2: Hoo_p | K2: 121-R-Hoo | L2: Passive | P2: ep.ba | Q2: Episyrphus balteatus | R2: Steven Braun | S2: 1 | T2: 0 | U2: 1 | V2: 0 | X2: 080523 | Y2: Morphological | Z2: MNHNL164755 | AA2: december 2024 | AB2: =IF(COUNTIF(Z:Z, Z2)>1, "Duplicate", "Unique") -> Unique
A3: =D3&"_"&E3&"_"&G3&"_"&J3&"_"&P3 -> 87_1_240821_AdH_p_my.fl | B3: 49.68734 | C3: 6.03495 | D3: 87 | E3: 1 | F3: 170821 | G3: 240821 | H3: 2021 | I3: {=_xludf.XLOOKUP(#REF!,'Feuille 16'!A:A,'Feuille 16'!B:B)} -> #NAME? | J3: AdH_p | K3: 090-R-AdH | L3: Passive | N3: 2 | P3: my.fl | Q3: Myathropa florea | R3: Hinatea Ariey | S3: 2 | T3: 0 | U3: 2 | V3: 0 | X3: 080523 | Y3: Morphological | Z3: MNHNL164757 | AA3: december 2024 | AB3: =IF(COUNTIF(Z:Z, Z3)>1, "Duplicate", "Unique") -> Unique
A4: =D4&"_"&E4&"_"&G4&"_"&J4&"_"&P4 -> 42_1_210621_Och_p_ep.ba | B4: 49.86226 | C4: 5.823835 | D4: 42 | E4: 1 | G4: 210621 | H4: 2021 | I4: {=_xludf.XLOOKUP(#REF!,'Feuille 16'!A:A,'Feuille 16'!B:B)} -> #NAME? | J4: Och_p | K4: 044-R-Och | L4: Passive | M4: Olivier Kirsch | N4: 1 | P4: ep.ba | Q4: Episyrphus balteatus | R4: Stephanie Lippert | S4: 1 | T4: 0 | U4: 1 | V4: 0 | X4: 150523 | Y4: Morphological | Z4: MNHNL164761 | AA4: december 2024 | AB4: =IF(COUNTIF(Z:Z, Z4)>1, "Duplicate", "Unique") -> Unique
A5: =D5&"_"&E5&"_"&G5&"_"&J5&"_"&P5 -> 6_1_080921_Con_p_vo.pe | B5: 50.13374 | C5: 6.047537 | D5: 6 | E5: 1 | G5: 080921 | H5: 2021 | I5: {=_xludf.XLOOKUP(#REF!,'Feuille 16'!A:A,'Feuille 16'!B:B)} -> #NAME? | J5: Con_p | K5: 006-N-Con | L5: Passive | M5: Steven Braun | N5: 2 | P5: vo.pe | Q5: Volucella pellucens | R5: Hinatea Ariey | S5: 1 | T5: 0 | U5: 1 | V5: 0 | X5: 160523 | Y5: Morphological | Z5: MNHNL164815 | AA5: december 2024 | AB5: =IF(COUNTIF(Z:Z, Z5)>1, "Duplicate", "Unique") -> Unique
A6: =D6&"_"&E6&"_"&G6&"_"&J6&"_"&P6 -> 114_1_240821_Gro_p_ep.ba | B6: 49.55828 | C6: 5.945858 | D6: 114 | E6: 1 | F6: 170821 | G6: 240821 | H6: 2021 | I6: {=_xludf.XLOOKUP(#REF!,'Feuille 16'!A:A,'Feuille 16'!B:B)} -> #NAME? | J6: Gro_p | K6: 109-N-Gro | L6: Passive | N6: 5 | P6: ep.ba | Q6: Episyrphus balteatus | R6: Hinatea Ariey | S6: 4 | T6: 1 | U6: 3 | V6: 0 | X6: 160523 | Y6: Morphological | Z6: MNHNL164774 | AA6: december 2024 | AB6: =IF(COUNTIF(Z:Z, Z6)>1, "Duplicate", "Unique") -> Unique
A7: =D7&"_"&E7&"_"&G7&"_"&J7&"_"&P7 -> 64_1_060921_Red_p_ep.ba | B7: 49.76281 | C7: 5.88665 | D7: 64 | E7: 1 | F7: 300821 | G7: 060921 | H7: 2021 | I7: Danielle Dolisy, Imen Kharrat | J7: Red_p | K7: 066-R-Red | L7: Passive | M7: Sam Schaack | N7: 15 | O7: pre-formation | P7: ep.ba | Q7: Episyrphus balteatus | R7: Hinatea Ariey | S7: 2 | T7: 0 | U7: 2 | V7: 0 | X7: 250523 | Y7: Morphological | Z7: MNHNL164801 | AA7: december 2024 | AB7: =IF(COUNTIF(Z:Z, Z7)>1, "Duplicate", "Unique") -> Unique
A8: =D8&"_"&E8&"_"&G8&"_"&J8&"_"&P8 -> 14_1_070921_Bai_p_ep.ba | B8: 50.01869 | C8: 5.921794 | D8: 14 | E8: 1 | F8: 310821 | G8: 070921 | H8: 2021 | I8: {=_xludf.XLOOKUP(#REF!,'Feuille 16'!A:A,'Feuille 16'!B:B)} -> #NAME? | J8: Bai_p | K8: 014-R-Bai | L8: Passive | M8: Olivier Kirsch; Chanistya Ayu Purnomo (2nd sorter) | P8: ep.ba | Q8: Episyrphus balteatus | R8: Hinatea Ariey | S8: 1 | T8: 0 | U8: 1 | V8: 0 | X8: 120623 | Y8: Morphological | Z8: MNHNL164767 | AA8: december 2024 | AB8: =IF(COUNTIF(Z:Z, Z8)>1, "Duplicate", "Unique") -> Unique
A9: =D9&"_"&E9&"_"&G9&"_"&J9&"_"&P9 -> 14_1_070921_Bai_p_rh.ca | B9: 50.01869 | C9: 5.921794 | D9: 14 | E9: 1 | F9: 310821 | G9: 070921 | H9: 2021 | I9: {=_xludf.XLOOKUP(#REF!,'Feuille 16'!A:A,'Feuille 16'!B:B)} -> #NAME? | J9: Bai_p | K9: 014-R-Bai | L9: Passive | M9: Olivier Kirsch; Chanistya Ayu Purnomo (2nd sorter) | P9: rh.ca | Q9: Rhingia campestris | R9: Hinatea Ariey | S9: 2 | T9: 2 | U9: 0 | V9: 0 | X9: 120623 | Y9: Morphological | Z9: MNHNL168000 | AA9: december 2024 | AB9: =IF(COUNTIF(Z:Z, Z9)>1, "Duplicate", "Unique") -> Unique
A10: =D10&"_"&E10&"_"&G10&"_"&J10&"_"&P10 -> 87_1_240821_AdH_p_ep.ba | B10: 49.68734 | C10: 6.03495 | D10: 87 | E10: 1 | F10: 170821 | G10: 240821 | H10: 2021 | I10: {=_xludf.XLOOKUP(#REF!,'Feuille 16'!A:A,'Feuille 16'!B:B)} -> #NAME? | J10: AdH_p | K10: 090-R-AdH | L10: Passive | M10: Hinatea Ariey (2nd sorter) | P10: ep.ba | Q10: Episyrphus balteatus | S10: 1 | T10: 0 | U10: 1 | V10: 0 | X10: 130623 | Y10: Morphological | Z10: MNHNL164175 | AA10: december 2024 | AB10: =IF(COUNTIF(Z:Z, Z10)>1, "Duplicate", "Unique") -> Unique
A11: =D11&"_"&E11&"_"&G11&"_"&J11&"_"&P11 -> 87_1_240821_AdH_p_ep.ba | B11: 49.68734 | C11: 6.03495 | D11: 87 | E11: 1 | F11: 170821 | G11: 240821 | H11: 2021 | I11: {=_xludf.XLOOKUP(#REF!,'Feuille 16'!A:A,'Feuille 16'!B:B)} -> #NAME? | J11: AdH_p | K11: 090-R-AdH | L11: Passive | M11: Hinatea Ariey (2nd sorter) | P11: ep.ba | Q11: Episyrphus balteatus | R11: Eleonore Pottier | S11: 1 | T11: 1 | U11: 0 | V11: 0 | X11: 040723 | Y11: Morphological | Z11: MNHNL164818 | AA11: december 2024 | AB11: =IF(COUNTIF(Z:Z, Z11)>1, "Duplicate", "Unique") -> Unique
A12: =D12&"_"&E12&"_"&G12&"_"&J12&"_"&P12 -> 67_1_240821_Mer_p_ep.ba | B12: 49.76001 | C12: 6.078149 | D12: 67 | E12: 1 | F12: 170821 | G12: 240821 | H12: 2021 | I12: {=_xludf.XLOOKUP(#REF!,'Feuille 16'!A:A,'Feuille 16'!B:B)} -> #NAME? | J12: Mer_p | K12: 069-N-Mer | L12: Passive | M12: Hinatea Ariey | N12: 2 | P12: ep.ba | Q12: Episyrphus balteatus | R12: Hinatea Ariey | S12: 1 | T12: 0 | U12: 1 | V12: 0 | X12: 150623 | Y12: Morphological | Z12: MNHNL164796 | AA12: december 2024 | AB12: =IF(COUNTIF(Z:Z, Z12)>1, "Duplicate", "Unique") -> Unique
A13: =D13&"_"&E13&"_"&G13&"_"&J13&"_"&P13 -> 82_1_210621_Joh_p_ep.ba | B13: 49.74085 | C13: 6.389209 | D13: 82 | E13: 1 | F13: 140621 | G13: 210621 | H13: 2021 | I13: {=_xludf.XLOOKUP(#REF!,'Feuille 16'!A:A,'Feuille 16'!B:B)} -> #NAME? | J13: Joh_p | K13: 073-R-Joh | L13: Passive | M13: Chanistya Ayu Purnomo | N13: 2 | P13: ep.ba | Q13: Episyrphus balteatus | R13: Chanistya Ayu Purnomo | S13: 2 | T13: 1 | U13: 1 | V13: 0 | X13: 220623 | Y13: Morphological | Z13: MNHNL164770 | AA13: december 2024 | AB13: =IF(COUNTIF(Z:Z, Z13)>1, "Duplicate", "Unique") -> Unique
A14: =D14&"_"&E14&"_"&G14&"_"&J14&"_"&P14 -> 96_2_100921_Trans_p_ep.ba | B14: 49.647259 | C14: 6.013814 | D14: 96 | E14: 2 | G14: 100921 | H14: 2021 | I14: {=_xludf.XLOOKUP(#REF!,'Feuille 16'!A:A,'Feuille 16'!B:B)} -> #NAME? | J14: Trans_p | K14: Transect2 | L14: Passive | M14: Hinatea Ariey | N14: 1 | P14: ep.ba | Q14: Episyrphus balteatus | R14: Hinatea Ariey | S14: 1 | T14: 1 | U14: 0 | V14: 0 | X14: 260623 | Y14: Morphological | Z14: MNHNL164781 | AA14: december 2024 | AB14: =IF(COUNTIF(Z:Z, Z14)>1, "Duplicate", "Unique") -> Unique
A15: =D15&"_"&E15&"_"&G15&"_"&J15&"_"&P15 -> 56_1_061021_Kie_p_ep.ba | B15: 49.83343 | C15: 6.136983 | D15: 56 | E15: 1 | F15: 310921 | G15: 061021 | H15: 2021 | I15: Fernanda Herrera-Mesías, Frida Pallapies | J15: Kie_p | K15: 048-N-Kie | L15: Passive | M15: Hinatea Ariey | N15: 1 | P15: ep.ba | Q15: Episyrphus balteatus | R15: Hinatea Ariey | S15: 1 | T15: 1 | U15: 0 | V15: 0 | X15: 260623 | Y15: Morphological | Z15: MNHNL164782 | AA15: december 2024 | AB15: =IF(COUNTIF(Z:Z, Z15)>1, "Duplicate", "Unique") -> Unique
A16: 101_1_250821_odF_p_ep.ba | B16: 49.64898 | C16: 6.416152 | D16: 101 | E16: 1 | F16: 170821 | G16: 240821 | H16: 2021 | I16: Fernanda Herrera-Mesías, Frida Pallapies, Antonio Do Rosario Cruz | J16: odF_p | K16: 095-R-odF | L16: Passive | M16: Chanistya Ayu Purnomo | N16: 4 | P16: ep.ba | Q16: Episyrphus balteatus | R16: Chanistya Ayu Purnomo | S16: 3 | T16: 0 | U16: 3 | V16: 0 | X16: 300623 | Y16: Morphological | Z16: MNHNL164786 | AA16: december 2024 | AB16: =IF(COUNTIF(Z:Z, Z16)>1, "Duplicate", "Unique") -> Unique
A17: 101_2_250821_Wen_p_ep.ba | B17: 49.61655 | C17: 6.348536 | D17: 101 | E17: 2 | F17: 170821 | G17: 240821 | H17: 2021 | I17: Fernanda Herrera-Mesías, Frida Pallapies, Antonio Do Rosario Cruz | J17: Wen_p | K17: 105-N-Wen | L17: Passive | M17: Chanistya Ayu Purnomo | N17: 2 | P17: ep.ba | Q17: Episyrphus balteatus | R17: Chanistya Ayu Purnomo | S17: 1 | T17: 0 | U17: 1 | V17: 0 | X17: 300623 | Y17: Morphological | Z17: MNHNL164763 | AA17: december 2024 | AB17: =IF(COUNTIF(Z:Z, Z17)>1, "Duplicate", "Unique") -> Unique
A18: =D18&"_"&E18&"_"&G18&"_"&J18&"_"&P18 -> 77_1_240821_Roe_p_ep.ba | B18: 49.7092 | C18: 6.05072 | D18: 77 | E18: 1 | F18: 170821 | G18: 240821 | H18: 2021 | I18: {=_xludf.XLOOKUP(#REF!,'Feuille 16'!A:A,'Feuille 16'!B:B)} -> #NAME? | J18: Roe_p | K18: 079-R-Roe | L18: Passive | M18: Amanda Luttringer | N18: 4 | P18: ep.ba | Q18: Episyrphus balteatus | R18: Chanistya Ayu Purnomo | S18: 1 | T18: 1 | U18: 0 | V18: 0 | X18: 300623 | Y18: Morphological | Z18: MNHNL164765 | AA18: december 2024 | AB18: =IF(COUNTIF(Z:Z, Z18)>1, "Duplicate", "Unique") -> Unique
A19: =D19&"_"&E19&"_"&G19&"_"&J19&"_"&P19 -> 94_1_240821_Mou_p_ep.ba | B19: 49.62638 | C19: 5.8965 | D19: 94 | E19: 1 | F19: 170821 | G19: 240821 | H19: 2021 | I19: {=_xludf.XLOOKUP(#REF!,'Feuille 16'!A:A,'Feuille 16'!B:B)} -> #NAME? | J19: Mou_p | K19: 098-R-Mou | L19: Passive | M19: Amanda Luttringer | N19: 39 | P19: ep.ba | Q19: Episyrphus balteatus | R19: Chanistya Ayu Purnomo | S19: 2 | T19: 1 | U19: 1 | V19: 0 | X19: 300623 | Y19: Morphological | Z19: MNHNL164772 | AA19: december 2024 | AB19: =IF(COUNTIF(Z:Z, Z19)>1, "Duplicate", "Unique") -> Unique
A20: =D20&"_"&E20&"_"&G20&"_"&J20&"_"&P20 -> 12_1_070921_Kal_p_sy.pi | B20: 50.10318 | C20: 6.13344 | D20: 12 | E20: 1 | F20: 010921 | G20: 070921 | H20: 2021 | I20: {=_xludf.XLOOKUP(#REF!,'Feuille 16'!A:A,'Feuille 16'!B:B)} -> #NAME? | J20: Kal_p | K20: 007-R-Kal | L20: Passive | M20: Chanistya Ayu Purnomo | N20: 11 | P20: sy.pi | Q20: Syritta pipiens | R20: Chanistya Ayu Purnomo | S20: 1 | T20: 0 | U20: 1 | V20: 0 | X20: 050723 | Y20: Morphological | Z20: MNHNL164788 | AA20: december 2024 | AB20: =IF(COUNTIF(Z:Z, Z20)>1, "Duplicate", "Unique") -> Unique
A21: =D21&"_"&E21&"_"&G21&"_"&J21&"_"&P21 -> 12_1_070921_Kal_p_my.fl | B21: 50.10318 | C21: 6.13344 | D21: 12 | E21: 1 | F21: 010921 | G21: 070921 | H21: 2021 | I21: {=_xludf.XLOOKUP(#REF!,'Feuille 16'!A:A,'Feuille 16'!B:B)} -> #NAME? | J21: Kal_p | K21: 007-R-Kal | L21: Passive | M21: Chanistya Ayu Purnomo | N21: 11 | P21: my.fl | Q21: Myathropa florea | R21: Chanistya Ayu Purnomo | S21: 1 | T21: 0 | U21: 1 | V21: 0 | X21: 050723 | Y21: Morphological | Z21: MNHNL164780 | AA21: december 2024 | AB21: =IF(COUNTIF(Z:Z, Z21)>1, "Duplicate", "Unique") -> Unique
A22: =D22&"_"&E22&"_"&G22&"_"&J22&"_"&P22 -> 113_1_160821_Gad_a_ep.ba | B22: 49.53475 | C22: 5.92937 | D22: 113 | E22: 1 | G22: 160821 | H22: 2021 | I22: {=_xludf.XLOOKUP(#REF!,'Feuille 16'!A:A,'Feuille 16'!B:B)} -> #NAME? | J22: Gad_a | K22: 117-N-Gad | L22: Active | M22: Sam Schaack | P22: ep.ba | Q22: Episyrphus balteatus | R22: Hinatea Ariey | S22: 1 | T22: 0 | U22: 1 | V22: 0 | X22: 220621 | Y22: Morphological | Z22: MNHNL164768 | AA22: december 2024 | AB22: =IF(COUNTIF(Z:Z, Z22)>1, "Duplicate", "Unique") -> Unique
A23: =D23&"_"&E23&"_"&G23&"_"&J23&"_"&P23 -> 95_1_240821_Sch_p_my.fl | B23: 49.61583 | C23: 5.967378 | D23: 95 | E23: 1 | F23: 160821 | G23: 240821 | H23: 2021 | I23: {=_xludf.XLOOKUP(#REF!,'Feuille 16'!A:A,'Feuille 16'!B:B)} -> #NAME? | J23: Sch_p | K23: 099-N-Sch | L23: Passive | M23: Chanistya Ayu Purnomo (2nd sorter) | N23: 9 | O23: +2 syrpidae found (1 headless) | P23: my.fl | Q23: Myathropa florea | R23: Chanistya Ayu Purnomo | S23: 1 | T23: 1 | U23: 0 | V23: 0 | X23: 060723 | Y23: Morphological | Z23: MNHNL164805 | AA23: december 2024 | AB23: =IF(COUNTIF(Z:Z, Z23)>1, "Duplicate", "Unique") -> Unique
A24: =D24&"_"&E24&"_"&G24&"_"&J24&"_"&P24 -> 95_1_240821_Sch_p_ep.ba | B24: 49.61583 | C24: 5.967378 | D24: 95 | E24: 1 | F24: 160821 | G24: 240821 | H24: 2021 | I24: {=_xludf.XLOOKUP(#REF!,'Feuille 16'!A:A,'Feuille 16'!B:B)} -> #NAME? | J24: Sch_p | K24: 099-N-Sch | L24: Passive | M24: Chanistya Ayu Purnomo (2nd sorter) | N24: 9 | O24: +2 syrpidae found (1 headless) | P24: ep.ba | Q24: Episyrphus balteatus | R24: Chanistya Ayu Purnomo | S24: 5 | T24: 4 | U24: 1 | V24: 0 | X24: 060723 | Y24: Morphological | Z24: MNHNL164800 | AA24: december 2024 | AB24: =IF(COUNTIF(Z:Z, Z24)>1, "Duplicate", "Unique") -> Unique
A25: =D25&"_"&E25&"_"&G25&"_"&J25&"_"&P25 -> 99_1_250821_GCGD_p_ep.ba | B25: 49.638566 | C25: 6.2126922 | D25: 99 | E25: 1 | F25: 190821 | G25: 250821 | H25: 2021 | I25: {=_xludf.XLOOKUP(#REF!,'Feuille 16'!A:A,'Feuille 16'!B:B)} -> #NAME? | J25: GCGD_p | K25: 102-N-GCGD | L25: Passive | M25: Sam Schaack | N25: 2 | P25: ep.ba | Q25: Episyrphus balteatus | R25: Chanistya Ayu Purnomo | S25: 2 | T25: 1 | U25: 1 | V25: 0 | X25: 060723 | Y25: Morphological | Z25: MNHNL164806 | AA25: december 2024 | AB25: =IF(COUNTIF(Z:Z, Z25)>1, "Duplicate", "Unique") -> Unique
A26: =D26&"_"&E26&"_"&G26&"_"&J26&"_"&P26 -> 72_1_260821_Gie_p_ep.ba | B26: 49.78318 | C26: 6.480582 | D26: 72 | E26: 1 | F26: 180821 | G26: 260821 | H26: 2021 | I26: {=_xludf.XLOOKUP(#REF!,'Feuille 16'!A:A,'Feuille 16'!B:B)} -> #NAME? | J26: Gie_p | K26: 063-R-Gie | L26: Passive | M26: Hinatea Ariey | N26: a lot | P26: ep.ba | Q26: Episyrphus balteatus | R26: Chanistya Ayu Purnomo | S26: 51 | T26: 18 | U26: 33 | V26: 0 | X26: 070723 | Y26: Morphological | Z26: MNHNL164762 | AA26: december 2024 | AB26: =IF(COUNTIF(Z:Z, Z26)>1, "Duplicate", "Unique") -> Unique
A27: =D27&"_"&E27&"_"&G27&"_"&J27&"_"&P27 -> 96_1_240821_Tos_p_vo.zo | B27: 49.62404 | C27: 6.043285 | D27: 96 | E27: 1 | F27: 160821 | G27: 240821 | H27: 2021 | I27: {=_xludf.XLOOKUP(#REF!,'Feuille 16'!A:A,'Feuille 16'!B:B)} -> #NAME? | J27: Tos_p | K27: 100-R-Tos | L27: Passive | M27: Olivier Kirsch | N27: 2 | P27: vo.zo | Q27: Volucella zonaria | R27: Chanistya Ayu Purnomo | S27: 1 | T27: 0 | U27: 1 | V27: 0 | X27: 070723 | Y27: Morphological | Z27: MNHNL164816 | AA27: december 2024 | AB27: =IF(COUNTIF(Z:Z, Z27)>1, "Duplicate", "Unique") -> Unique
A28: =D28&"_"&E28&"_"&G28&"_"&J28&"_"&P28 -> 96_1_240821_Tos_p_ep.ba | B28: 49.62404 | C28: 6.043285 | D28: 96 | E28: 1 | F28: 160821 | G28: 240821 | H28: 2021 | I28: {=_xludf.XLOOKUP(#REF!,'Feuille 16'!A:A,'Feuille 16'!B:B)} -> #NAME? | J28: Tos_p | K28: 100-R-Tos | L28: Passive | M28: Olivier Kirsch | P28: ep.ba | Q28: Episyrphus balteatus | R28: Eleonore Pottier | S28: 1 | T28: 1 | U28: 0 | V28: 0 | X28: 050723 | Y28: Morphological | Z28: MNHNL164178 | AA28: december 2024 | AB28: =IF(COUNTIF(Z:Z, Z28)>1, "Duplicate", "Unique") -> Unique
A29: =D29&"_"&E29&"_"&G29&"_"&J29&"_"&P29 -> 52_1_070921_udA_p_ep.ba | B29: 49.81124 | C29: 5.814094 | D29: 52 | E29: 1 | F29: 310821 | G29: 070921 | H29: 2021 | I29: {=_xludf.XLOOKUP(#REF!,'Feuille 16'!A:A,'Feuille 16'!B:B)} -> #NAME? | J29: udA_p | K29: 054-R-udA | L29: Passive | M29: Hinatea Ariey | N29: 18 | P29: ep.ba | Q29: Episyrphus balteatus | R29: Chanistya Ayu Purnomo | S29: 2 | T29: 1 | U29: 1 | V29: 0 | X29: 240723 | Y29: Morphological | Z29: MNHNL164795 | AA29: december 2024 | AB29: =IF(COUNTIF(Z:Z, Z29)>1, "Duplicate", "Unique") -> Unique
A30: =D30&"_"&E30&"_"&G30&"_"&J30&"_"&P30 -> 28_1_110422_Fas_a_ep.ba | B30: 49.93818 | C30: 5.94657 | D30: 28 | E30: 1 | F30: NA | G30: 110422 | H30: 2022 | I30: {=_xludf.XLOOKUP(#REF!,'Feuille 16'!A:A,'Feuille 16'!B:B)} -> #NAME? | J30: Fas_a | K30: 029-N-Fas | L30: Active | M30: Chanistya Ayu Purnomo | N30: 5 | P30: ep.ba | Q30: Episyrphus balteatus | R30: Chanistya Ayu Purnomo | S30: 1 | T30: 0 | U30: 1 | V30: 0 | X30: 240723 | Y30: Morphological | Z30: MNHNL164807 | AA30: december 2024 | AB30: =IF(COUNTIF(Z:Z, Z30)>1, "Duplicate", "Unique") -> Unique
A31: =D31&"_"&E31&"_"&G31&"_"&J31&"_"&P31 -> 103_1_240821_Gei_p_ep.ba | B31: 49.54434 | C31: 5.854062 | D31: 103 | E31: 1 | F31: 170821 | G31: 240821 | H31: 2021 | I31: {=_xludf.XLOOKUP(#REF!,'Feuille 16'!A:A,'Feuille 16'!B:B)} -> #NAME? | J31: Gei_p | K31: 116-R-Gei | L31: Passive | M31: Chanistya Ayu Purnomo | N31: 4 | O31: 2 Ep.ba | P31: ep.ba | Q31: Episyrphus balteatus | R31: Chanistya Ayu Purnomo | S31: 2 | T31: 0 | U31: 2 | V31: 0 | X31: 240723 | Y31: Morphological | Z31: MNHNL164814 | AA31: december 2024 | AB31: =IF(COUNTIF(Z:Z, Z31)>1, "Duplicate", "Unique") -> Unique
A32: =D32&"_"&E32&"_"&G32&"_"&J32&"_"&P32 -> 72_1_260821_Gie_p_ep.ba | B32: 49.78318 | C32: 6.480582 | D32: 72 | E32: 1 | F32: 180821 | G32: 260821 | H32: 2021 | I32: {=_xludf.XLOOKUP(#REF!,'Feuille 16'!A:A,'Feuille 16'!B:B)} -> #NAME? | J32: Gie_p | K32: 063-R-Gie | L32: Passive | M32: Hinatea Ariey | N32: a lot | P32: ep.ba | Q32: Episyrphus balteatus | R32: Chanistya Ayu Purnomo | S32: 1 | T32: 1 | U32: 0 | V32: 0 | X32: 250723 | Y32: Morphological | Z32: MNHNL164184 | AA32: december 2024 | AB32: =IF(COUNTIF(Z:Z, Z32)>1, "Duplicate", "Unique") -> Unique
A33: =D33&"_"&E33&"_"&G33&"_"&J33&"_"&P33 -> 82_1_260821_Joh_p_ep.ba | B33: 49.74085 | C33: 6.389209 | D33: 82 | E33: 1 | F33: 140621 | G33: 260821 | H33: 2021 | I33: {=_xludf.XLOOKUP(#REF!,'Feuille 16'!A:A,'Feuille 16'!B:B)} -> #NAME? | J33: Joh_p | K33: 073-R-Joh | L33: Passive | M33: Hinatea Ariey | N33: 17 | O33: 2 E. balteatus(already ID and removed not counted in the total) | P33: ep.ba | Q33: Episyrphus balteatus | R33: Hinatea Ariey | S33: 2 | T33: 0 | U33: 2 | V33: 0 | X33: 040723 | Y33: Morphological | Z33: MNHNL164812 | AA33: december 2024 | AB33: =IF(COUNTIF(Z:Z, Z33)>1, "Duplicate", "Unique") -> Unique
A34: =D34&"_"&E34&"_"&G34&"_"&J34&"_"&P34 -> 87_1_240821_Pra_p_ep.ba | B34: 49.65445 | C34: 6.02472 | D34: 87 | E34: 1 | F34: 160821 | G34: 240821 | H34: 2021 | I34: {=_xludf.XLOOKUP(#REF!,'Feuille 16'!A:A,'Feuille 16'!B:B)} -> #NAME? | J34: Pra_p | K34: 090-N-Pra | L34: Passive | M34: Lydia Barrouche | P34: ep.ba | Q34: Episyrphus balteatus | R34: Eleonore Pottier | S34: 5 | T34: 3 | U34: 2 | V34: 0 | X34: 250723 | Y34: Morphological | Z34: MNHNL164180 | AA34: december 2024 | AB34: =IF(COUNTIF(Z:Z, Z34)>1, "Duplicate", "Unique") -> Unique
A35: =D35&"_"&E35&"_"&G35&"_"&J35&"_"&P35 -> 96_1_240821_Kaz_p_ep.ba | B35: 49.64296 | C35: 6.022347 | D35: 96 | E35: 1 | F35: 160821 | G35: 240821 | H35: 2021 | I35: {=_xludf.XLOOKUP(#REF!,'Feuille 16'!A:A,'Feuille 16'!B:B)} -> #NAME? | J35: Kaz_p | K35: 100-N-Kaz | L35: Passive | M35: Hinatea Ariey | N35: 9 | P35: ep.ba | Q35: Episyrphus balteatus | R35: Chanistya Ayu Purnomo | S35: 1 | T35: 0 | U35: 1 | V35: 0 | X35: 250723 | Y35: Morphological | Z35: MNHNL164176 | AA35: december 2024 | AB35: =IF(COUNTIF(Z:Z, Z35)>1, "Duplicate", "Unique") -> Unique
A36: =D36&"_"&E36&"_"&G36&"_"&J36&"_"&P36 -> 96_1_240821_Kaz_p_ep.ba | B36: 49.64296 | C36: 6.022347 | D36: 96 | E36: 1 | F36: 160821 | G36: 240821 | H36: 2021 | I36: {=_xludf.XLOOKUP(#REF!,'Feuille 16'!A:A,'Feuille 16'!B:B)} -> #NAME? | J36: Kaz_p | K36: 100-N-Kaz | L36: Passive | M36: Hinatea Ariey | N36: 9 | P36: ep.ba | Q36: Episyrphus balteatus | R36: Chanistya Ayu Purnomo | S36: 1 | T36: 0 | U36: 1 | V36: 0 | X36: 250723 | Y36: Morphological | Z36: MNHNL178229 | AB36: =IF(COUNTIF(Z:Z, Z36)>1, "Duplicate", "Unique") -> Unique
A37: =D37&"_"&E37&"_"&G37&"_"&J37&"_"&P37 -> 48_1_100921_Wan_p_ep.ba | B37: 49.8715 | C37: 6.275446 | D37: 48 | E37: 1 | F37: 020921 | G37: 100921 | H37: 2021 | I37: {=_xludf.XLOOKUP(#REF!,'Feuille 16'!A:A,'Feuille 16'!B:B)} -> #NAME? | J37: Wan_p | K37: 041-R-Wan | L37: Passive | M37: Chanistya Ayu Purnomo | N37: 11 | O37: 1 Ep.ba | P37: ep.ba | Q37: Episyrphus balteatus | R37: Chanistya Ayu Purnomo | S37: 1 | T37: 0 | U37: 1 | V37: 0 | X37: 250723 | Y37: Morphological | Z37: MNHNL164811 | AA37: december 2024 | AB37: =IF(COUNTIF(Z:Z, Z37)>1, "Duplicate", "Unique") -> Unique
A38: =D38&"_"&E38&"_"&G38&"_"&J38&"_"&P38 -> 48_1_100921_Wan_p_rh.ca | B38: 49.8715 | C38: 6.275446 | D38: 48 | E38: 1 | F38: 020921 | G38: 100921 | H38: 2021 | I38: {=_xludf.XLOOKUP(#REF!,'Feuille 16'!A:A,'Feuille 16'!B:B)} -> #NAME? | J38: Wan_p | K38: 041-R-Wan | L38: Passive | M38: Chanistya Ayu Purnomo | N38: 11 | O38: 1 Ep.ba | P38: rh.ca | Q38: Rhingia campestris | R38: Chanistya Ayu Purnomo | S38: 5 | T38: 1 | U38: 4 | V38: 0 | X38: 250723 | Y38: Morphological | Z38: MNHNL168014 | AA38: december 2024 | AB38: =IF(COUNTIF(Z:Z, Z38)>1, "Duplicate", "Unique") -> Unique
A39: =D39&"_"&E39&"_"&G39&"_"&J39&"_"&P39 -> 96_2_300821_Trans2_p_ep.ba | B39: 49.647259 | C39: 6.013814 | D39: 96 | E39: 2 | F39: 190821 | G39: 300821 | H39: 2021 | I39: {=_xludf.XLOOKUP(#REF!,'Feuille 16'!A:A,'Feuille 16'!B:B)} -> #NAME? | J39: Trans2_p | K39: Transect 2 | L39: Passive | M39: Sam Schaack | N39: 20 | O39: Incomplete info on red pot | P39: ep.ba | Q39: Episyrphus balteatus | R39: Chanistya Ayu Purnomo | S39: 3 | T39: 2 | U39: 1 | V39: 0 | X39: 250723 | Y39: Morphological | Z39: MNHNL164789 | AA39: december 2024 | AB39: =IF(COUNTIF(Z:Z, Z39)>1, "Duplicate", "Unique") -> Unique
A40: =D40&"_"&E40&"_"&G40&"_"&J40&"_"&P40 -> 86_1_060921_Koe_p_rh.ca | B40: 49.68346 | C40: 5.94073 | D40: 86 | E40: 1 | F40: 300821 | G40: 060921 | H40: 2021 | I40: {=_xludf.XLOOKUP(#REF!,'Feuille 16'!A:A,'Feuille 16'!B:B)} -> #NAME? | J40: Koe_p | K40: 089-R-Koe | L40: Passive | M40: Sam Schaack | N40: 7 | O40: pre-formation | P40: rh.ca | Q40: Rhingia campestris | R40: Chanistya Ayu Purnomo | S40: 2 | T40: 2 | U40: 0 | V40: 0 | X40: 250723 | Y40: Morphological | Z40: MNHNL165825 | AA40: december 2024 | AB40: =IF(COUNTIF(Z:Z, Z40)>1, "Duplicate", "Unique") -> Unique
...

Sheet Feuille 16
B1: Collectors S1
A2: 001-R-Hel050522 | B2: Fernanda Herrera Mesias, Alena Susic
A3: 007-R-Kal050522 | B3: Fernanda Herrera Mesias, Alena Susic
A4: 002-N-iCo050522 | B4: Fernanda Herrera Mesias, Alena Susic
A5: 003-N-Ani050522 | B5: Fernanda Herrera Mesias, Alena Susic
A6: 005-N-adW060522 | B6: Fernanda Herrera Mesias, Alena Susic
A7: 006-N-odW060522 | B7: Fernanda Herrera Mesias, Alena Susic
A8: 014-R-Bai210422 | B8: Danielle Dolisy, Imen Kharrat
A9: 004-N-ioA210422 | B9: Danielle Dolisy, Imen Kharrat
A10: 005-N-iKo210422 | B10: Danielle Dolisy, Imen Kharrat
A11: 010-N-Ahe210422 | B11: Danielle Dolisy, Imen Kharrat
A12: 011-N-Den210422 | B12: Danielle Dolisy, Imen Kharrat
A13: 011-N-idR210422 | B13: Danielle Dolisy, Imen Kharrat
A14: 044-R-Och190422
A15: 054-R-udA190422
A16: 022-N-aHa190422
A17: 029-N-Fas190422
A18: 034-N-ikWx
A19: 043-N-Der190422
A20: 046-N-Don030522 | B20: Fernanda Herrera Mesias, Alena Susic
A21: 047-N-Sai030522 | B21: Fernanda Herrera Mesias, Alena Susic
A22: 057-N-Gro030522 | B22: Fernanda Herrera Mesias, Alena Susic
A23: 048-R-Dit030522 | B23: Fernanda Herrera Mesias, Alena Susic
A24: 047-N-War30522 | B24: Fernanda Herrera Mesias, Alena Susic
A25: 068-N-Mes30522 | B25: Fernanda Herrera Mesias, Alena Susic
A26: 041-R-Wanx
A27: 050-N-Schx
A28: 024-R-Saux
A29: 012-N-idBx
A30: 025-N-idFx
A31: 033-N-Aflx
A32: 066-R-Red190422 | B32: Danielle Dolisy, Imen Kharrat
A33: 067-N-Wie190422 | B33: Danielle Dolisy, Imen Kharrat
A34: 089-R-Koe190422 | B34: Danielle Dolisy, Imen Kharrat
A35: 066-N-Bec190422 | B35: Danielle Dolisy, Imen Kharrat
A36: 067-N-Sae190422 | B36: Danielle Dolisy, Imen Kharrat
A37: 077-N-JWW190422 | B37: Danielle Dolisy, Imen Kharrat
A38: 091-N-Bri200422 | B38: Danielle Dolisy, Imen Kharrat
A39: 069-N-Meh200422 | B39: Danielle Dolisy, Imen Kharrat
A40: 099-N-Bru200422 | B40: Danielle Dolisy, Imen Kharrat
...

Sheet 2021
A1: Name | B1: Latitude | C1: Longitude | D1: CELL | E1: STATION | G1: Season 1 | J1: Collectors S1 | K1: Team S1 | L1: Season 2 | O1: Collectors S2 | P1: Team S2 | Q1: Season 3 | T1: Collectors S3 | U1: Team S3 | W1: date on jar
A2: 001-N-Fol | B2: 50.15681 | C2: 5.999387 | D2: 1 | E2: 1 | G2: 130421 | H2: 220421 | I2: =A2&H2 -> 001-N-Fol220421 | J2: Kaja Joeris | K2: B | L2: 170621 | M2: 300621 | N2: =A2&M2 -> 001-N-Fol300621 | O2: Elena Breitenberger, Dylan Thyssen | P2: B | Q2: 10921 | R2: 070921 | S2: =A2&R2 -> 001-N-Fol070921 | T2: Fernanda Herrera-Mesías, Frida Pallapies | U2: B
A3: 001-R-Hel | B3: 50.16656 | C3: 5.980226 | D3: 1 | E3: 1 | G3: 130421 | H3: 220421 | I3: =A3&H3 -> 001-R-Hel220421 | J3: Kaja Joeris | K3: B | L3: 160621 | M3: 300621 | N3: =A3&M3 -> 001-R-Hel300621 | O3: Elena Breitenberger, Dylan Thyssen | P3: B | Q3: 10921 | R3: 070921 | S3: =A3&R3 -> 001-R-Hel070921 | T3: Fernanda Herrera-Mesías, Frida Pallapies | U3: B
A4: 002-N-adS | B4: 50.1682 | C4: 6.013868 | D4: 2 | E4: 1 | G4: 130421 | H4: 220421 | I4: =A4&H4 -> 002-N-adS220421 | J4: Kaja Joeris | K4: B | L4: 160621 | M4: 300621 | N4: =A4&M4 -> 002-N-adS300621 | O4: Elena Breitenberger, Dylan Thyssen | P4: B | Q4: 10921 | R4: 070921 | S4: =A4&R4 -> 002-N-adS070921 | T4: Fernanda Herrera-Mesías, Frida Pallapies | U4: B
A5: 006-N-Con | B5: 50.13374 | C5: 6.047537 | D5: 6 | E5: 1 | G5: 130421 | H5: 220421 | I5: =A5&H5 -> 006-N-Con220421 | J5: Kaja Joeris | K5: B | L5: 170621 | M5: 300621 | N5: =A5&M5 -> 006-N-Con300621 | O5: Elena Breitenberger, Dylan Thyssen | P5: B | Q5: 20921 | R5: 080921 | S5: =A5&R5 -> 006-N-Con080921 | T5: Fernanda Herrera-Mesías, Frida Pallapies | U5: B
A6: 007-N-Gei | B6: 50.1339 | C6: 6.113742 | D6: 7 | E6: 2 | G6: 140421 | H6: 220421 | I6: =A6&H6 -> 007-N-Gei220421 | J6: Kaja Joeris | K6: B | L6: 170621 | M6: 300621 | N6: =A6&M6 -> 007-N-Gei300621 | O6: Elena Breitenberger, Dylan Thyssen | P6: B | Q6: 20921 | R6: 080921 | S6: =A6&R6 -> 007-N-Gei080921 | T6: Fernanda Herrera-Mesías, Frida Pallapies | U6: B
A7: 007-R-Kal | B7: 50.10318 | C7: 6.13344 | D7: 12 | E7: 1 | G7: 140421 | H7: 220421 | I7: =A7&H7 -> 007-R-Kal220421 | J7: Kaja Joeris | K7: B | L7: 160621 | M7: 300621 | N7: =A7&M7 -> 007-R-Kal300621 | O7: Elena Breitenberger, Dylan Thyssen | P7: B | Q7: 10921 | R7: 070921 | S7: =A7&R7 -> 007-R-Kal070921 | T7: Fernanda Herrera-Mesías, Frida Pallapies | U7: B
A8: 012-N-Hei | B8: 50.09435 | C8: 6.07863 | D8: 12 | E8: 1 | G8: 140421 | H8: 220421 | I8: =A8&H8 -> 012-N-Hei220421 | J8: Kaja Joeris | K8: B | L8: 160621 | M8: 300621 | N8: =A8&M8 -> 012-N-Hei300621 | O8: Elena Breitenberger, Dylan Thyssen | P8: B | Q8: 20921 | R8: 080921 | S8: =A8&R8 -> 012-N-Hei080921 | T8: Fernanda Herrera-Mesías, Frida Pallapies | U8: B
A9: 008-N-Hab | B9: 50.05841 | C9: 5.860713 | D9: 13 | E9: 1 | G9: 130421 | H9: 270421 | I9: =A9&H9 -> 008-N-Hab270421 | J9: Imen Kharrat, Alex Weigand, Danielle Dolisy | K9: A | L9: 140621 | M9: 210621 | N9: =A9&M9 -> 008-N-Hab210621 | O9: Imen Kharrat, Danielle Dolisy | P9: A | Q9: 310821 | R9: 070921 | S9: =A9&R9 -> 008-N-Hab070921 | T9: Danielle Dolisy, Imen Kharrat | U9: A
A10: 009-N-Ram | B10: 50.06473 | C10: 5.910962 | D10: 9 | E10: 1 | G10: 130421 | H10: 280421 | I10: =A10&H10 -> 009-N-Ram280421 | J10: Imen Kharrat, Alex Weigand, Danielle Dolisy | K10: A | L10: 140621 | M10: 210621 | N10: =A10&M10 -> 009-N-Ram210621 | O10: Imen Kharrat, Danielle Dolisy | P10: A | Q10: 310821 | R10: 070921 | S10: =A10&R10 -> 009-N-Ram070921 | T10: Danielle Dolisy, Imen Kharrat | U10: A
A11: 014-N-Mue | B11: 50.02771 | C11: 5.865552 | D11: 14 | E11: 1 | G11: 130421 | H11: 280421 | I11: =A11&H11 -> 014-N-Mue280421 | J11: Imen Kharrat, Alex Weigand, Danielle Dolisy | K11: A | L11: 140621 | M11: 210621 | N11: =A11&M11 -> 014-N-Mue210621 | O11: Imen Kharrat, Danielle Dolisy | P11: A | Q11: 310821 | R11: 070921 | S11: =A11&R11 -> 014-N-Mue070921 | T11: Danielle Dolisy, Imen Kharrat | U11: A
A12: 014-R-Bai | B12: 50.01869 | C12: 5.921794 | D12: 14 | E12: 1 | G12: 130421 | H12: 270421 | I12: =A12&H12 -> 014-R-Bai270421 | J12: Imen Kharrat, Alex Weigand, Danielle Dolisy | K12: A | L12: 140621 | M12: 210621 | N12: =A12&M12 -> 014-R-Bai210621 | O12: Imen Kharrat, Danielle Dolisy | P12: A | Q12: 310821 | R12: 070921 | S12: =A12&R12 -> 014-R-Bai070921 | T12: Danielle Dolisy, Imen Kharrat | U12: A
A13: 016-N-Fen | B13: 50.04119 | C13: 6.008988 | D13: 16 | E13: 1 | G13: 130421 | H13: 270421 | I13: =A13&H13 -> 016-N-Fen270421 | J13: Imen Kharrat, Alex Weigand, Danielle Dolisy | K13: A | L13: 140621 | M13: 210621 | N13: =A13&M13 -> 016-N-Fen210621 | O13: Imen Kharrat, Danielle Dolisy | P13: A | Q13: 310821 | R13: 070921 | S13: =A13&R13 -> 016-N-Fen070921 | T13: Danielle Dolisy, Imen Kharrat | U13: A
... A20: 055-N-Eer | B20: 49.81286 | C20: 5.924067 | D20: 53 | E20: 1 | G20: 140421 | H20: 200421 | I20: =A20&H20 -> 055-N-Eer200421 | J20: Caroline Grounds, Dylan Thissen, Balint Andrasi, Senyu Zhu | K20: C | L20: 150621 | M20: 220621 | N20: =A20&M20 -> 055-N-Eer220621 | O20: Dylan Thissen, Caroline Grounds | P20: C | Q20: 310821 | R20: 070921 | S20: =A20&R20 -> 055-N-Eer070921 | T20: Dylan Thissen, Tabea Theis | U20: C
A21: 056-N-Hon | B21: 49.79059 | C21: 5.951342 | D21: 54 | E21: 1 | I21: =A21&H21 -> 056-N-Hon | N21: =A21&M21 -> 056-N-Hon | S21: =A21&R21 -> 056-N-Hon
A22: 056-N-Pre | B22: 49.80236 | C22: 5.948428 | D22: 54 | E22: 1 | I22: =A22&H22 -> 056-N-Pre | N22: =A22&M22 -> 056-N-Pre | S22: =A22&R22 -> 056-N-Pre
A23: 046-N-Don | B23: 49.84038 | C23: 5.981982 | D23: 44 | E23: 1 | I23: =A23&H23 -> 046-N-Don | N23: =A23&M23 -> 046-N-Don | S23: =A23&R23 -> 046-N-Don
A24: 046-N-Neu | B24: 49.84043 | C24: 5.945002 | D24: 44 | E24: 1 | I24: =A24&H24 -> 046-N-Neu | N24: =A24&M24 -> 046-N-Neu | S24: =A24&R24 -> 046-N-Neu
A25: 046-N-Haa | B25: 49.84005 | C25: 5.963105 | D25: 44 | E25: 1 | I25: =A25&H25 -> 046-N-Haa | N25: =A25&M25 -> 046-N-Haa | S25: =A25&R25 -> 046-N-Haa
A26: 047-N-Sai | B26: 49.82748 | C26: 6.012677 | D26: 55 | E26: 1 | I26: =A26&H26 -> 047-N-Sai | N26: =A26&M26 -> 047-N-Sai | S26: =A26&R26 -> 047-N-Sai
A27: 047-N-War | B27: 49.86547 | C27: 6.04727 | D27: 45 | E27: 2 | G27: 10421 | H27: 80421 | I27: =A27&H27 -> 047-N-War80421 | J27: Kaja Joeris | K27: B | L27: 140621 | M27: 250621 | N27: =A27&M27 -> 047-N-War250621 | O27: Elena Breitenberger, S Ogan | P27: B | Q27: 310921 | R27: 61021 | S27: =A27&R27 -> 047-N-War61021 | T27: Fernanda Herrera-Mesías, Frida Pallapies | U27: B | W27: 60921 | X27: solved, no syrphidae found for S3
A28: 048-N-Kie | B28: 49.83343 | C28: 6.136983 | D28: 56 | E28: 1 | G28: 10422 | H28: 80421 | I28: =A28&H28 -> 048-N-Kie80421 | J28: Kaja Joeris | K28: B | L28: 150621 | M28: 250621 | N28: =A28&M28 -> 048-N-Kie250621 | O28: Dylan Thissen, Caroline Grounds, Elena Breitenberger | P28: C | Q28: 310921 | R28: 61021 | S28: =A28&R28 -> 048-N-Kie61021 | T28: Fernanda Herrera-Mesías, Frida Pallapies | U28: B | W28: 60921 | X28: Problem
A29: 048-R-Dit | B29: 49.83849 | C29: 6.109265 | D29: 46 | E29: 1 | G29: 10421 | H29: 80421 | I29: =A29&H29 -> 048-R-Dit80421 | J29: Kaja Joeris | K29: B | L29: 140621 | M29: 250621 | N29: =A29&M29 -> 048-R-Dit250621 | O29: Dylan Thissen, Caroline Grounds, Elena Breitenberger | P29: C | Q29: 310921 | R29: 61021 | S29: =A29&R29 -> 048-R-Dit61021 | T29: Fernanda Herrera-Mesías, Frida Pallapies | U29: B
A30: 056-N-Tho | B30: 49.8215 | C30: 5.981009 | D30: 54 | E30: 1 | I30: =A30&H30 -> 056-N-Tho | N30: =A30&M30 -> 056-N-Tho | S30: =A30&R30 -> 056-N-Tho
A31: 057-N-Kie | B31: 49.78586 | C31: 6.067229 | D31: 66 | E31: 2 | I31: =A31&H31 -> 057-N-Kie | N31: =A31&M31 -> 057-N-Kie | S31: =A31&R31 -> 057-N-Kie
A32: 057-N-Maa | B32: 49.79563 | C32: 6.053376 | D32: 55 | E32: 1 | G32: 10420 | H32: 80421 | I32: =A32&H32 -> 057-N-Maa80421 | J32: Kaja Joeris | K32: B | L32: 150621 | M32: 250621 | N32: =A32&M32 -> 057-N-Maa250621 | O32: Dylan Thissen, Caroline Grounds, Elena Breitenberger | P32: C | Q32: 310921 | R32: 61021 | S32: =A32&R32 -> 057-N-Maa61021 | T32: Fernanda Herrera-Mesías, Frida Pallapies | U32: B | W32: 060921 | X32: Problem
A33: 058-N-Gro | B33: 49.78884 | C33: 6.078819 | D33: 67 | E33: 2 | G33: 10421 | H33: 80421 | I33: =A33&H33 -> 058-N-Gro80421 | J33: Kaja Joeris | K33: B | L33: 140621 | M33: 250621 | N33: =A33&M33 -> 058-N-Gro250621 | O33: Elena Breitenberger, S Ogan | P33: B | Q33: 310921 | R33: 61021 | S33: =A33&R33 -> 058-N-Gro61021 | T33: Fernanda Herrera-Mesías, Frida Pallapies | U33: B | W33: 250621 | X33: solved
A34: 030-N-adK | B34: 49.94568 | C34: 6.032212 | D34: 29 | E34: 2 | G34: 140421 | H34: 200421 | I34: =A34&H34 -> 030-N-adK200421 | J34: Caroline Grounds, Balint Andrasi, Dylan Thissen | K34: C | L34: 150621 | M34: 220621 | N34: =A34&M34 -> 030-N-adK220621 | O34: Dylan Thissen, Caroline Grounds | P34: C | Q34: 20921 | R34: 090921 | S34: =A34&R34 -> 030-N-adK090921 | T34: Dylan Thissen, Tabea Theis | U34: C
A35: 032-N-Sch | B35: 49.92203 | C35: 6.144177 | D35: 39 | E35: 3 | G35: 150421 | H35: 220421 | I35: =A35&H35 -> 032-N-Sch220421 | J35: Caroline Grounds, Balint Andrasi, Dylan Thissen | K35: C | L35: 150621 | M35: 220621 | N35: =A35&M35 -> 032-N-Sch220621 | O35: Dylan Thissen, Caroline Grounds | P35: C | Q35: 20921 | R35: 100921 | S35: =A35&R35 -> 032-N-Sch100921 | T35: Dylan Thissen, Tabea Theis | U35: C
A36: 040-N-Mar | B36: 49.89874 | C36: 6.208736 | D36: 39 | E36: 1 | G36: 150421 | H36: 220421 | I36: =A36&H36 -> 040-N-Mar220421 | J36: Caroline Grounds, Balint Andrasi, Dylan Thissen | K36: C | L36: 160621 | M36: 240621 | N36: =A36&M36 -> 040-N-Mar240621 | O36: Dylan Thissen, Caroline Grounds | P36: C | Q36: 20921 | R36: 100921 | S36: =A36&R36 -> 040-N-Mar100921 | T36: Dylan Thissen, Tabea Theis | U36: C
A37: 040-N-Tan | B37: 49.88991 | C37: 6.188913 | D37: 39 | E37: 1 | G37: 150421 | H37: 220421 | I37: =A37&H37 -> 040-N-Tan220421 | J37: Caroline Grounds, Balint Andrasi, Dylan Thissen | K37: C | L37: 160621 | M37: 240621 | N37: =A37&M37 -> 040-N-Tan240621 | O37: Dylan Thissen, Caroline Grounds | P37: C | Q37: 020921 | R37: 100921 | S37: =A37&R37 -> 040-N-Tan100921 | T37: Dylan Thissen, Tabea Theis | U37: C
A38: 041-R-Wan | B38: 49.8715 | C38: 6.275446 | D38: 48 | E38: 1 | G38: 150421 | H38: 220421 | I38: =A38&H38 -> 041-R-Wan220421 | J38: Caroline Grounds, Balint Andrasi, Dylan Thissen | K38: C | L38: 160621 | M38: 240621 | N38: =A38&M38 -> 041-R-Wan240621 | O38: Dylan Thissen, Caroline Grounds | P38: C | Q38: 20921 | R38: 100921 | S38: =A38&R38 -> 041-R-Wan100921 | T38: Dylan Thissen, Tabea Theis | U38: C
A39: 050-N-Sch | B39: 49.84228 | C39: 6.256113 | D39: 48 | E39: 2 | I39: =A39&H39 -> 050-N-Sch | N39: =A39&M39 -> 050-N-Sch | S39: =A39&R39 -> 050-N-Sch
A40: 051-N-Rei | B40: 49.8424 | C40: 6.339193 | D40: 49 | E40: 1 | I40: =A40&H40 -> 051-N-Rei | N40: =A40&M40 -> 051-N-Rei | S40: =A40&R40 -> 051-N-Rei
A41: 024-R-Sau | B41: 49.98732 | C41: 6.096952 | D41: 23 | E41: 1 | G41: 140421 | H41: 200421 | I41: =A41&H41 -> 024-R-Sau200421 | J41: Caroline Grounds, Balint Andrasi, Dylan Thissen, Senyu Zhu | K41: C | L41: 150621 | M41: 220621 | N41: =A41&M41 -> 024-R-Sau220621 | O41: Dylan Thissen, Caroline Grounds | P41: C | Q41: 020921 | R41: 090921 | S41: =A41&R41 -> 024-R-Sau090921 | T41: Dylan Thissen, Tabea Theis | U41: C
A42: 057-N-Gro | B42: 49.78439 | C42: 6.007607 | D42: 66 | E42: 3 | I42: =A42&H42 -> 057-N-Gro | N42: =A42&M42 -> 057-N-Gro | S42: =A42&R42 -> 057-N-Gro
A43: 065-N-Wie | B43: 49.75423 | C43: 5.81804 | D43: 63 | E43: 1 | G43: 230321 | H43: 300321 | I43: =A43&H43 -> 065-N-Wie300321 | J43: Imen Kharrat, Alex Weigand | K43: A | L43: 160621 | M43: 220621 | N43: =A43&M43 -> 065-N-Wie220621 | O43: Imen Kharrat, Danielle Dolisy | P43: A | Q43: 300821 | R43: 60921 | S43: =A43&R43 -> 065-N-Wie60921 | T43: Danielle Dolisy, Imen Kharrat | U43: A
A44: 066-R-Red | B44: 49.76281 | C44: 5.88665 | D44: 64 | E44: 1 | G44: 230321 | H44: 300321 | I44: =A44&H44 -> 066-R-Red300321 | J44: Imen Kharrat, Alex Weigand | K44: A | L44: 160621 | M44: 220621 | N44: =A44&M44 -> 066-R-Red220621 | O44: Imen Kharrat, Danielle Dolisy | P44: A | Q44: 300821 | R44: 60921 | S44: =A44&R44 -> 066-R-Red60921 | T44: Danielle Dolisy, Imen Kharrat | U44: A
A45: 067-N-Wie | B45: 49.7652 | C45: 5.955758 | D45: 65 | E45: 2 | I45: =A45&H45 -> 067-N-Wie | N45: =A45&M45 -> 067-N-Wie | S45: =A45&R45 -> 067-N-Wie
A46: 076-N-Obe | B46: 49.73203 | C46: 5.84678 | D46: 74 | E46: 1 | G46: 230321 | H46: 300321 | I46: =A46&H46 -> 076-N-Obe300321 | J46: Imen Kharrat, Alex Weigand | K46: A | L46: 160621 | M46: 220621 | N46: =A46&M46 -> 076-N-Obe220621 | O46: Imen Kharrat, Danielle Dolisy | P46: A | Q46: 300821 | R46: 60921 | S46: =A46&R46 -> 076-N-Obe60921 | T46: Danielle Dolisy, Imen Kharrat | U46: A
...

Sheet 2022
A1: Site-ID_2019 | B1: 2021_1+2+3 | C1: 2022_1+2+3 | D1: Team | E1: Saison 1 | H1: Collectors S1 | I1: Saison 2 | L1: Collectors S2 | M1: Saison 3 | P1: Collectors S3 | Q1: year | R1: Cluster number | S1: site code | T1: CELL | U1: STATION | V1: region | W1: site name | X1: type | Y1: lat | Z1: long | AA1: contact | AB1: To Inform | AC1: aditionnal
B2: x | C2: x | D2: B | E2: 290422 | F2: 050522 | G2: =S2&F2 -> 001-R-Hel050522 | H2: Fernanda Herrera Mesias, Alena Susic | I2: ? | J2: 210622 | K2: =S2&J2 -> 001-R-Hel210622 | M2: 300822 | N2: 070922 | O2: =S2&N2 -> 001-R-Hel070922 | P2: Fernanda Herrera-Mesías, Alena Susic | Q2: R | R2: 1 | S2: 001-R-Hel | T2: 1 | U2: 1 | V2: Huldange | W2: in Helwen | X2: Prairie paturee en milieu humide | Y2: 50.16656106173789 | Z2: 5.980226383645738 | AA2: natur&ëmwelt
A3: 27 | B3: x | C3: x | D3: B | E3: 280422 | F3: 050522 | G3: =S3&F3 -> 007-R-Kal050522 | H3: Fernanda Herrera Mesias, Alena Susic | I3: ? | J3: 220622 | K3: =S3&J3 -> 007-R-Kal220622 | M3: 300822 | N3: 070922 | O3: =S3&N3 -> 007-R-Kal070922 | P3: Fernanda Herrera-Mesías, Alena Susic | Q3: R | R3: 1 | S3: 007-R-Kal | T3: 12 | U3: 1 | V3: Clerf | W3: Kalborner Mühle | X3: meadow close to the Our River | Y3: 50.10318 | Z3: 6.13344 | AA3: Frankie Thielen
C4: x | D4: B | E4: 280422 | F4: 050522 | G4: =S4&F4 -> 002-N-iCo050522 | H4: Fernanda Herrera Mesias, Alena Susic | I4: x | J4: 220622 | K4: =S4&J4 -> 002-N-iCo220622 | M4: 300822 | N4: 070922 | O4: =S4&N4 -> 002-N-iCo070922 | P4: Fernanda Herrera-Mesías, Alena Susic | Q4: 2022 | R4: 1 | S4: 002-N-iCo | T4: 6 | U4: 1 | W4: Troisvierges | X4: Im Conzenfenn | Y4: 50.14675 | Z4: 6.03671 | AB4: no
C5: x | D5: B | E5: 280422 | F5: 050522 | G5: =S5&F5 -> 003-N-Ani050522 | H5: Fernanda Herrera Mesias, Alena Susic | I5: ? | J5: 220622 | K5: =S5&J5 -> 003-N-Ani220622 | M5: 300822 | N5: 070922 | O5: =S5&N5 -> 003-N-Ani070922 | P5: Fernanda Herrera-Mesías, Alena Susic | Q5: 2022 | R5: 1 | S5: 003-N-Ani | T5: 3 | U5: 1 | W5: Weiswampach | X5: An Niddelbur | Y5: 50.15758 | Z5: 6.10034 | AB5: no
C6: x | D6: B | E6: 290422 | F6: 060522 | G6: =S6&F6 -> 005-N-adW060522 | H6: Fernanda Herrera Mesias, Alena Susic | I6: ? | J6: 210622 | K6: =S6&J6 -> 005-N-adW210622 | M6: 10922 | N6: 070922 | O6: =S6&N6 -> 005-N-adW070922 | P6: Fernanda Herrera-Mesías, Alena Susic | Q6: 2022 | R6: 1 | S6: 005-N-adW | T6: 5 | U6: 1 | W6: Troisvierges | X6: Auf der untersten Woltz | Y6: 50.13441 | Z6: 5.98489 | AB6: no
C7: x | D7: B | E7: 290422 | F7: 060522 | G7: =S7&F7 -> 006-N-odW060522 | H7: Fernanda Herrera Mesias, Alena Susic | I7: ? | J7: 220622 | K7: =S7&J7 -> 006-N-odW220622 | M7: 300822 | N7: 070922 | O7: =S7&N7 -> 006-N-odW070922 | P7: Fernanda Herrera-Mesías, Alena Susic | Q7: 2022 | R7: 1 | S7: 006-N-odW | T7: 11 | U7: 1 | W7: Wincrange | X7: Op der Wilwert | Y7: 50.10359 | Z7: 6.00556 | AB7: no
B8: x | C8: x | D8: A | E8: 110422 | F8: 210422 | G8: =S8&F8 -> 014-R-Bai210422 | H8: Danielle Dolisy, Imen Kharrat | I8: 140622 | J8: 200622 | K8: =S8&J8 -> 014-R-Bai200622 | M8: 050922 | N8: 120922 | O8: =S8&N8 -> 014-R-Bai120922 | P8: Danielle Dolisy, Alexander Weigand | Q8: R | R8: 2 | S8: 014-R-Bai | T8: 14 | U8: 1 | V8: Wincrange | W8: a Baierbich | X8: Prairie paturee en milieu humide | Y8: 50.018691 | Z8: 5.921794 | AA8: natur&ëmwelt
C9: x | D9: A | E9: 110422 | F9: 210422 | G9: =S9&F9 -> 004-N-ioA210422 | H9: Danielle Dolisy, Imen Kharrat | I9: 140622 | J9: 200622 | K9: =S9&J9 -> 004-N-ioA200622 | M9: 050922 | N9: 120922 | O9: =S9&N9 -> 004-N-ioA120922 | P9: Danielle Dolisy, Alexander Weigand | Q9: 2022 | R9: 2 | S9: 004-N-ioA | T9: 9 | U9: 1 | W9: Wincrange | X9: In der obersten Alheck | Y9: 50.09726 | Z9: 5.90267 | AB9: no
C10: x | D10: A | E10: 110422 | F10: 210422 | G10: =S10&F10 -> 005-N-iKo210422 | H10: Danielle Dolisy, Imen Kharrat | I10: 140622 | J10: 200622 | K10: =S10&J10 -> 005-N-iKo200622 | M10: 050922 | N10: 120922 | O10: =S10&N10 -> 005-N-iKo120922 | P10: Danielle Dolisy, Alexander Weigand | Q10: 2022 | R10: 2 | S10: 005-N-iKo | T10: 10 | U10: 1 | W10: Wincrange | X10: In Koppricht | Y10: 50.09977 | Z10: 5.94047 | AB10: no
C11: x | D11: A | E11: 110422 | F11: 210422 | G11: =S11&F11 -> 010-N-Ahe210422 | H11: Danielle Dolisy, Imen Kharrat | I11: 140622 | J11: 200622 | K11: =S11&J11 -> 010-N-Ahe200622 | M11: 050922 | N11: 120922 | O11: =S11&N11 -> 010-N-Ahe120922 | P11: Danielle Dolisy, Alexander Weigand | Q11: 2022 | R11: 2 | S11: 010-N-Ahe | T11: 10 | U11: 1 | W11: Wincrange | X11: Auf Hemischt | Y11: 50.08814 | Z11: 5.94542 | AB11: no
C12: x | D12: A | E12: 110422 | F12: 210422 | G12: =S12&F12 -> 011-N-Den210422 | H12: Danielle Dolisy, Imen Kharrat | I12: 140622 | J12: 200622 | K12: =S12&J12 -> 011-N-Den200622 | M12: 050922 | N12: 120922 | O12: =S12&N12 -> 011-N-Den120922 | P12: Danielle Dolisy, Alexander Weigand | Q12: 2022 | R12: 2 | S12: 011-N-Den | T12: 11 | U12: 1 | W12: Wincrange | X12: Denschwies | Y12: 50.07463 | Z12: 6.02228 | AB12: no
C13: x | D13: A | E13: 110422 | F13: 210422 | G13: =S13&F13 -> 011-N-idR210422 | H13: Danielle Dolisy, Imen Kharrat | I13: 150622 | J13: 200622 | K13: =S13&J13 -> 011-N-idR200622 | M13: 050922 | N13: 120922 | O13: =S13&N13 -> 011-N-idR120922 | P13: Danielle Dolisy, Alexander Weigand | Q13: 2022 | R13: 2 | S13: 011-N-idR | T13: 11 | U13: 1 | W13: Clervaux | X13: In der Reichelbach | Y13: 50.07086 | Z13: 6.00101 | AB13: no
B14: x | C14: x | D14: C | E14: ? | F14: 190422 | G14: =S14&F14 -> 044-R-Och190422 | I14: ? | J14: 210622 | K14: =S14&J14 -> 044-R-Och210622 | M14: 170822 | N14: 240822 | O14: =S14&N14 -> 044-R-Och240822 | P14: Eric Stöver, Kai Jäckels, Dylan Thissen | Q14: R | R14: 3 | S14: 044-R-Och | T14: 42 | U14: 1 | V14: Rambrouch | W14: Ochelter | X14: Prairie paturee en milieu humide | Y14: 49.86226446150461 | Z14: 5.823834985519833 | AA14: natur&ëmwelt
B15: x | C15: x | D15: C | E15: ? | F15: 190422 | G15: =S15&F15 -> 054-R-udA190422 | I15: x | J15: x | K15: =S15&J15 -> 054-R-udAx | M15: 170822 | N15: 240822 | O15: =S15&N15 -> 054-R-udA240822 | P15: Eric Stöver, Kai Jäckels, Dylan Thissen | Q15: R | R15: 3 | S15: 054-R-udA | T15: 52 | U15: 1 | V15: Rambrouch/Ell | W15: Unter dem Ahlenweg | X15: Prairie paturee en milieu humide | Y15: 49.811244 | Z15: 5.814094 | AA15: natur&ëmwelt
C16: x | D16: C | E16: ? | F16: 190422 | G16: =S16&F16 -> 022-N-aHa190422 | I16: ? | J16: 210622 | K16: =S16&J16 -> 022-N-aHa210622 | M16: 160822 | N16: 230822 | O16: =S16&N16 -> 022-N-aHa230822 | P16: Eric Stöver, Kai Jäckels, Dylan Thissen | Q16: 2022 | R16: 3 | S16: 022-N-aHa | T16: 21 | U16: 1 | W16: Kiischpelt | X16: auf Haschleid | Y16: 49.992064 | Z16: 5.9831866 | AB16: no | AC16: Eichenwald
C17: x | D17: C | E17: 110422 | F17: 190422 | G17: =S17&F17 -> 029-N-Fas190422 | I17: ? | J17: 210622 | K17: =S17&J17 -> 029-N-Fas210622 | M17: 160822 | N17: 230822 | O17: =S17&N17 -> 029-N-Fas230822 | P17: Eric Stöver, Kai Jäckels, Dylan Thissen | Q17: 2022 | R17: 3 | S17: 029-N-Fas | T17: 28 | U17: 1 | W17: Buederscheid | X17: Fassbich | Y17: 49.93818 | Z17: 5.94657 | AB17: no
C18: x | D18: C | E18: x | F18: x | G18: =S18&F18 -> 034-N-ikWx | I18: ? | J18: 210622 | K18: =S18&J18 -> 034-N-ikW210622 | M18: 160822 | N18: 230822 | O18: =S18&N18 -> 034-N-ikW230822 | P18: Eric Stöver, Kai Jäckels, Dylan Thissen | Q18: 2022 | R18: 3 | S18: 034-N-ikW | T18: 33 | U18: 1 | W18: Surre | X18: In klein Wellestein | Y18: 49.89591 | Z18: 5.75332 | AB18: no | AC18: Waldrand
C19: x | D19: C | E19: ? | F19: 190422 | G19: =S19&F19 -> 043-N-Der190422 | I19: x | J19: 210622 | K19: =S19&J19 -> 043-N-Der210622 | M19: 170822 | N19: 240822 | O19: =S19&N19 -> 043-N-Der240822 | P19: Eric Stöver, Kai Jäckels, Dylan Thissen | Q19: 2022 | R19: 3 | S19: 043-N-Der | T19: 41 | U19: 1 | W19: Bigonville | X19: In Dermicht | Y19: 49.84173 | Z19: 5.79058 | AB19: no
C20: x | D20: B | E20: 270422 | F20: 030522 | G20: =S20&F20 -> 046-N-Don030522 | H20: Fernanda Herrera Mesias, Alena Susic | I20: 300622 | J20: 060722 | K20: =S20&J20 -> 046-N-Don060722 | M20: 290822 | N20: 050922 | O20: =S20&N20 -> 046-N-Don050922 | P20: Fernanda Herrera-Mesías, Alena Susic | Q20: 2022 | R20: 4 | S20: 046-N-Don | T20: 44 | U20: 1 | W20: MertzV019, Donneschleed | X20: Ackerbuntbrache SICONA | Y20: 49.840384 | Z20: 5.981982 | AA20: SICONA
C21: x | D21: B | E21: 270422 | F21: 030522 | G21: =S21&F21 -> 047-N-Sai030522 | H21: Fernanda Herrera Mesias, Alena Susic | I21: 300622 | J21: 060722 | K21: =S21&J21 -> 047-N-Sai060722 | M21: 290822 | N21: 050922 | O21: =S21&N21 -> 047-N-Sai050922 | P21: Fernanda Herrera-Mesías, Alena Susic | Q21: 2022 | R21: 4 | S21: 047-N-Sai | T21: 55 | U21: 1 | W21: MertzS015, Säitert | X21: Weiher (Mahd SICONA). Bongert davor wird wanderbeweidet | Y21: 49.82748 | Z21: 6.012677 | AA21: SICONA
C22: x | D22: B | E22: 270422 | F22: 030522 | G22: =S22&F22 -> 057-N-Gro030522 | H22: Fernanda Herrera Mesias, Alena Susic | I22: 300622 | J22: 060722 | K22: =S22&J22 -> 057-N-Gro060722 | M22: 290822 | N22: 050922 | O22: =S22&N22 -> 057-N-Gro050922 | P22: Fernanda Herrera-Mesías, Alena Susic | Q22: 2022 | R22: 4 | S22: 057-N-Gro | T22: 66 | U22: 3 | V22: Bissen | W22: BisseS005, Grousst Muer | X22: BK04 B, BK06 C Mahd SICONA | Y22: 49.784392 | Z22: 6.007607 | AA22: SICONA
B23: x | C23: x | D23: B | E23: 270422 | F23: 030522 | G23: =S23&F23 -> 048-R-Dit030522 | H23: Fernanda Herrera Mesias, Alena Susic | I23: 290622 | J23: 060722 | K23: =S23&J23 -> 048-R-Dit060722 | M23: 290822 | N23: 050922 | O23: =S23&N23 -> 048-R-Dit050922 | P23: Fernanda Herrera-Mesías, Alena Susic | Q23: R | R23: 4 | S23: 048-R-Dit | T23: 46 | U23: 1 | V23: Ettelbrück | W23: in der Ditchesbach | X23: Streuobstwiese | Y23: 49.83849393366019 | Z23: 6.109265363017441 | AA23: natur&ëmwelt
C24: x | D24: B | E24: 270422 | F24: 30522 | G24: =S24&F24 -> 047-N-War30522 | H24: Fernanda Herrera Mesias, Alena Susic | I24: 290622 | J24: 060722 | K24: =S24&J24 -> 047-N-War060722 | M24: 290822 | N24: 050922 | O24: =S24&N24 -> 047-N-War050922 | P24: Fernanda Herrera-Mesías, Alena Susic | Q24: 2022 | R24: 4 | S24: 047-N-War | T24: 45 | U24: 2 | W24: Feulen | X24: FeuleS050, Warkdall | Y24: 49.86547 | Z24: 6.04727 | AB24: no | AC24: Nur umzäunter Weiher von SICONA bewirtschaftet
C25: x | D25: B | E25: 270422 | F25: 30522 | G25: =S25&F25 -> 068-N-Mes30522 | H25: Fernanda Herrera Mesias, Alena Susic | I25: 290622 | J25: 060722 | K25: =S25&J25 -> 068-N-Mes060722 | M25: 290822 | N25: 050922 | O25: =S25&N25 -> 068-N-Mes050922 | P25: Fernanda Herrera-Mesías, Alena Susic | Q25: 2022 | R25: 4 | S25: 068-N-Mes | T25: 66 | U25: 1 | W25: Mersch | X25: MerscS015, Béisener Weier /Béisener Wee | Y25: 49.7575 | Z25: 6.04784 | AB25: no | AC25: 6210 A Wanderbeweidung Schafe
B26: x | C26: x | D26: C | E26: x | F26: x | G26: =S26&F26 -> 041-R-Wanx | I26: ? | J26: 070722 | K26: =S26&J26 -> 041-R-Wan070722 | M26: 010922 | N26: 080922 | O26: =S26&N26 -> 041-R-Wan080922 | P26: Eric Stöver, Kai Jäckels | Q26: R | R26: 5 | S26: 041-R-Wan | T26: 48 | U26: 1 | V26: Reisdorf | W26: Wangersberg | X26: Jardin | Y26: 49.871495882489995 | Z26: 6.275445643812589 | AA26: natur&ëmwelt
C27: x | D27: C | E27: x | F27: x | G27: =S27&F27 -> 050-N-Schx | I27: ? | J27: 070722 | K27: =S27&J27 -> 050-N-Sch070722 | M27: 010922 | N27: 080922 | O27: =S27&N27 -> 050-N-Sch080922 | P27: Eric Stöver, Kai Jäckels | Q27: 2022 | R27: 5 | S27: 050-N-Sch | T27: 48 | U27: 2 | V27: Vallee de l'Ernz | W27: Schinneschgraecht | X27: Pelouse seche | Y27: 49.84227565924596 | Z27: 6.2561133656082095 | AA27: natur&ëmwelt
A28: 17 | B28: x | C28: x | D28: C | E28: x | F28: x | G28: =S28&F28 -> 024-R-Saux | I28: ? | J28: 060722 | K28: =S28&J28 -> 024-R-Sau060722 | M28: 010922 | N28: 080922 | O28: =S28&N28 -> 024-R-Sau080922 | P28: Eric Stöver, Kai Jäckels | Q28: R | R28: 5 | S28: 024-R-Sau | T28: 23 | U28: 1 | V28: Diekirch | W28: Sauerwisen | X28: meadow near river | Y28: 49.987316 | Z28: 6.096952 | AA28: NPOur Alain Klein, alain.klein@naturpark-our.lu
C29: x | D29: C | E29: x | F29: x | G29: =S29&F29 -> 012-N-idBx | I29: x | J29: 060722 | K29: =S29&J29 -> 012-N-idB060722 | M29: 010922 | N29: 080922 | O29: =S29&N29 -> 012-N-idB080922 | P29: Eric Stöver, Kai Jäckels | Q29: 2022 | R29: 5 | S29: 012-N-idB | T29: 17 | U29: 1 | W29: Parc Hosingen | X29: In den Birken | Y29: 50.05067 | Z29: 6.11837 | AB29: no
C30: x | D30: C | E30: x | F30: x | G30: =S30&F30 -> 025-N-idFx | I30: x | J30: 060722 | K30: =S30&J30 -> 025-N-idF060722 | M30: 010922 | N30: 080922 | O30: =S30&N30 -> 025-N-idF080922 | P30: Eric Stöver, Kai Jäckels | Q30: 2022 | R30: 5 | S30: 025-N-idF | T30: 31 | U30: 1 | W30: Putscheid | X30: In der Fischdell | Y30: 49.970457 | Z30: 6.1578753 | AB30: no | AC30: Eichenwald
C31: x | D31: C | E31: x | F31: x | G31: =S31&F31 -> 033-N-Aflx | I31: x | J31: 060722 | K31: =S31&J31 -> 033-N-Afl060722 | M31: 010922 | N31: 080922 | O31: =S31&N31 -> 033-N-Afl080922 | P31: Eric Stöver, Kai Jäckels | Q31: 2022 | R31: 5 | S31: 033-N-Afl | T31: 32 | U31: 1 | W31: Vianden | X31: Auf Flerschet | Y31: 49.937417 | Z31: 6.2146289 | AB31: no | AC31: Foret feuillue a dominance de chene
B32: x | C32: x | D32: A | E32: 120422 | F32: 190422 | G32: =S32&F32 -> 066-R-Red190422 | H32: Danielle Dolisy, Imen Kharrat | I32: 150622 | J32: 210622 | K32: =S32&J32 -> 066-R-Red210622 | M32: 060922 | N32: 130922 | O32: =S32&N32 -> 066-R-Red130922 | P32: Danielle Dolisy, Alexander Weigand | Q32: R | R32: 6 | S32: 066-R-Red | T32: 64 | U32: 1 | W32: RedanV004, Redange | X32: Weiher (Mahd SICONA) | Y32: 49.76281 | Z32: 5.88665 | AA32: SICONA
C33: x | D33: A | E33: 120422 | F33: 190422 | G33: =S33&F33 -> 067-N-Wie190422 | H33: Danielle Dolisy, Imen Kharrat | I33: 150622 | J33: 210622 | K33: =S33&J33 -> 067-N-Wie210622 | M33: 060922 | N33: 130922 | O33: =S33&N33 -> 067-N-Wie130922 | P33: Danielle Dolisy, Alexander Weigand | Q33: 2022 | R33: 6 | S33: 067-N-Wie | T33: 65 | U33: 2 | V33: Useldingen | W33: UseldS007, Weiden | X33: BK08 A Weiher (Mahd SICONA) | Y33: 49.765204 | Z33: 5.955758 | AA33: SICONA
A34: 25 | B34: x | C34: x | D34: A | E34: 120422 | F34: 190422 | G34: =S34&F34 -> 089-R-Koe190422 | H34: Danielle Dolisy, Imen Kharrat | I34: 150622 | J34: 210622 | K34: =S34&J34 -> 089-R-Koe210622 | M34: 60922 | N34: 130922 | O34: =S34&N34 -> 089-R-Koe130922 | P34: Danielle Dolisy, Alexander Weigand | Q34: R | R34: 6 | S34: 089-R-Koe | T34: 86 | U34: 1 | V34: Simmern | W34: Koerich | X34: private garden with ponds | Y34: 49.68346 | Z34: 5.94073 | AA34: Roland Proess; ecotop@pt.lu | AC34: date on the jar: 150922
C35: x | D35: A | E35: 120422 | F35: 190422 | G35: =S35&F35 -> 066-N-Bec190422 | H35: Danielle Dolisy, Imen Kharrat | I35: 150622 | J35: 210622 | K35: =S35&J35 -> 066-N-Bec210622 | M35: 60922 | N35: 130922 | O35: =S35&N35 -> 066-N-Bec130922 | P35: Danielle Dolisy, Alexander Weigand | Q35: 2022 | R35: 6 | S35: 066-N-Bec | T35: 75 | U35: 1 | W35: Beckerich | X35: BeckeV115 | Y35: 49.737104 | Z35: 5.9139304 | AB35: no | AC35: Näerdenerbaach, Bachrenaturierung. Wird von Landwirt beweidet, Beweidungspause Mitte Juni-Mitte August. SICONA fragt Bewirtschafter
C36: x | D36: A | E36: 120422 | F36: 190422 | G36: =S36&F36 -> 067-N-Sae190422 | H36: Danielle Dolisy, Imen Kharrat | I36: 150622 | J36: 210622 | K36: =S36&J36 -> 067-N-Sae210622 | M36: 60922 | N36: 130922 | O36: =S36&N36 -> 067-N-Sae130922 | P36: Danielle Dolisy, Alexander Weigand | Q36: 2022 | R36: 6 | S36: 067-N-Sae | T36: 65 | U36: 1 | W36: Saeul | X36: SaeulV001 | Y36: 49.744565 | Z36: 5.9739121 | AB36: no | AC36: Schwébecherbréck, Weiher mit kleinem Randstreifen, Wegrand mit Hochstaudenflur
C37: x | D37: A | E37: 120422 | F37: 190422 | G37: =S37&F37 -> 077-N-JWW190422 | H37: Danielle Dolisy, Imen Kharrat | I37: 150622 | J37: 210622 | K37: =S37&J37 -> 077-N-JWW210622 | M37: 60922 | N37: 130922 | O37: =S37&N37 -> 077-N-JWW130922 | P37: Danielle Dolisy, Alexander Weigand | Q37: 2022 | R37: 6 | S37: 077-N-JWW | T37: 85 | U37: 1 | W37: Hobscheid | X37: Jardin "Wëll Wolleg Landschaft" | Y37: 49.6916 | Z37: 5.91221 | AB37: yes | AC37: 19, rue de Kreuzerbuch in Hobscheid
A38: 2 | C38: x | D38: A | E38: 130422 | F38: 200422 | G38: =S38&F38 -> 091-N-Bri200422 | H38: Danielle Dolisy, Imen Kharrat | I38: 160622 | J38: 220622 | K38: =S38&J38 -> 091-N-Bri220622 | M38: 220822 | N38: 290822 | O38: =S38&N38 -> 091-N-Bri290822 | P38: Danielle Dolisy, Alexander Weigand | Q38: 2022 | R38: 7 | S38: 091-N-Bri | T38: 88 | U38: 1 | V38: Kopstal | W38: KopstV011, Bridel, Fënnef Buchen | X38: Renat. Heide (Wanderbeweidung Schafe), Waldrand | Y38: 49.667371 | Z38: 6.08171 | AA38: SICONA, Simone Schneider
C39: x | D39: A | E39: 130422 | F39: 200422 | G39: =S39&F39 -> 069-N-Meh200422 | H39: Danielle Dolisy, Imen Kharrat | I39: 160622 | J39: 220622 | K39: =S39&J39 -> 069-N-Meh220622 | M39: 220822 | N39: 290822 | O39: =S39&N39 -> 069-N-Meh290822 | P39: Danielle Dolisy, Alexander Weigand | Q39: 2022 | R39: 7 | S39: 069-N-Meh | T39: 67 | U39: 1 | W39: Mersch | X39: MerscV005 (MerscS014) | Y39: 49.745236 | Z39: 6.072072 | AB39: no | AC39: unbefestigter Weg mit alten Obstbäumen & Hecke, Mahd SICONA
A40: 7 | C40: x | D40: A | E40: 130422 | F40: 200422 | G40: =S40&F40 -> 099-N-Bru200422 | H40: Danielle Dolisy, Imen Kharrat | I40: 160622 | J40: 220622 | K40: =S40&J40 -> 099-N-Bru220622 | M40: 220822 | N40: 290822 | O40: =S40&N40 -> 099-N-Bru290822 | P40: Danielle Dolisy, Alexander Weigand | Q40: 2022 | R40: 7 | S40: 099-N-Bru | T40: 95 | U40: 1 | V40: Mamer | W40: MamerS024, Bruch | X40: meadow with ponds, BK11 A, 6510 B + BK06 A (Wanderbeweidung Schafe) | Y40: 49.629294 | Z40: 6.000515 | AA40: SICONA, Simone Schneider
...

Sheet Loic_MSc_Thesis
A1: Code | B1: Latitude | C1: Longitude | D1: Cell | E1: Station | F1: Date_in | G1: Date_out | H1: Année | I1: Collecteur | J1: Code site | K1: Nom du site | L1: Passive/active | M1: Sorter | N1: Number of specimens | O1: Notes | P1: Code ID | Q1: ID | R1: IDENTIFIER | S1: NUMBER OF SPECIMEN | T1: MALE | U1: FEMALE | V1: SEX INDETERMINATE | W1: IDENTIFICATION NOTE | X1: DATE OF IDENTIFICATION | Y1: IDENTIFICATION METHOD | Z1: QR code | AA1: Recorder? | AB1: Unique
A2: =D2&"_"&E2&"_"&G2&"_"&J2&"_"&P2 -> 117_4_030721_BW4_p_ch.bi | B2: 49.52651 | C2: 6.20790 | D2: 117 | E2: 4 | F2: 250621 | G2: 030721 | H2: 2021 | I2: Loic Hellers | J2: BW4_p | K2: BW4 | L2: Pan trap | M2: Chanistya Ayu Purnomo | N2: 6 | O2: 2 Ep.ba (1 specimen is in a bad condition) | P2: ch.bi | Q2: Chrysotoxum bicinctum | R2: Chanistya Ayu Purnomo | S2: 1 | T2: 0 | U2: 1 | V2: 0 | X2: 171023 | Y2: Morphological | Z2: MNHNL178021 | AB2: =IF(COUNTIF(Z:Z, Z2)>1, "Duplicate", "Unique") -> Unique
A3: =D3&"_"&E3&"_"&G3&"_"&J3&"_"&P3 -> 118_2_170721_BU2_p_ep.ba | B3: 49.52629 | C3: 6.23017 | D3: 118 | E3: 2 | F3: 030721 | G3: 170721 | H3: 2021 | I3: Loic Hellers | J3: BU2_p | K3: BU2 | L3: Pan trap | M3: Chanistya Ayu Purnomo | N3: 10 | O3: 2 Ep.ba | P3: ep.ba | Q3: Episyrphus balteatus | R3: Chanistya Ayu Purnomo | S3: 2 | T3: 1 | U3: 1 | V3: 0 | X3: 161023 | Y3: Morphological | Z3: MNHNL164720 | AA3: december 2024 | AB3: =IF(COUNTIF(Z:Z, Z3)>1, "Duplicate", "Unique") -> Unique
A4: =D4&"_"&E4&"_"&G4&"_"&J4&"_"&P4 -> 117_3_170721_BW2_1_p_ep.ba | B4: 49.53281 | C4: 6.20603 | D4: 117 | E4: 3 | F4: 030721 | G4: 170721 | H4: 2021 | I4: Loic Hellers | J4: BW2_1_p | K4: BW2 | L4: Pan trap | M4: Chanistya Ayu Purnomo | N4: 29 | O4: 24 Ep.ba | P4: ep.ba | Q4: Episyrphus balteatus | R4: Chanistya Ayu Purnomo | S4: 24 | T4: 16 | U4: 8 | V4: 0 | X4: 161023 | Y4: Morphological | Z4: MNHNL164146 | AA4: december 2024 | AB4: =IF(COUNTIF(Z:Z, Z4)>1, "Duplicate", "Unique") -> Unique
A5: =D5&"_"&E5&"_"&G5&"_"&J5&"_"&P5 -> 117_2_170721_BW1_p_ep.ba | B5: 49.54010 | C5: 6.17939 | D5: 117 | E5: 2 | F5: 030721 | G5: 170721 | H5: 2021 | I5: Loic Hellers | J5: BW1_p | K5: BW1 | L5: Pan trap | M5: Chanistya Ayu Purnomo | N5: 33 | O5: 22 Ep.ba | P5: ep.ba | Q5: Episyrphus balteatus | R5: Chanistya Ayu Purnomo | S5: 21 | T5: 10 | U5: 12 | V5: 0 | X5: 161023 | Y5: Morphological | Z5: MNHNL164145 | AA5: december 2024 | AB5: =IF(COUNTIF(Z:Z, Z5)>1, "Duplicate", "Unique") -> Unique
A6: =D6&"_"&E6&"_"&G6&"_"&J6&"_"&P6 -> 118_1_170721_BU1_2_p_ep.ba | B6: 49.53240 | C6: 6.22523 | D6: 118 | E6: 1 | F6: 030721 | G6: 170721 | H6: 2021 | I6: Loic Hellers | J6: BU1_2_p | K6: BU1 | L6: Pan trap | M6: Chanistya Ayu Purnomo | N6: 3 | O6: 2 Ep.ba | P6: ep.ba | Q6: Episyrphus balteatus | R6: Chanistya Ayu Purnomo | S6: 2 | T6: 1 | U6: 1 | V6: 0 | X6: 161023 | Y6: Morphological | Z6: MNHNL164713 | AA6: december 2024 | AB6: =IF(COUNTIF(Z:Z, Z6)>1, "Duplicate", "Unique") -> Unique
